ERROR 2017-02-08 10:18:03,424 views 6411 140350626912000 邮件发送失败: (535, b'5.7.8 authentication failed')ERROR 2017-10-07 10:11:28,866 exception 12102 140324119840512 Internal Server Error: /
Traceback (most recent call last):
  File "/home/ming/.env/blog/lib/python3.5/site-packages/django/db/backends/utils.py", line 64, in execute
    return self.cursor.execute(sql, params)
  File "/home/ming/.env/blog/lib/python3.5/site-packages/django/db/backends/mysql/base.py", line 112, in execute
    return self.cursor.execute(query, args)
  File "/home/ming/.env/blog/lib/python3.5/site-packages/pymysql/cursors.py", line 166, in execute
    result = self._query(query)
  File "/home/ming/.env/blog/lib/python3.5/site-packages/pymysql/cursors.py", line 322, in _query
    conn.query(q)
  File "/home/ming/.env/blog/lib/python3.5/site-packages/pymysql/connections.py", line 856, in query
    self._affected_rows = self._read_query_result(unbuffered=unbuffered)
  File "/home/ming/.env/blog/lib/python3.5/site-packages/pymysql/connections.py", line 1057, in _read_query_result
    result.read()
  File "/home/ming/.env/blog/lib/python3.5/site-packages/pymysql/connections.py", line 1340, in read
    first_packet = self.connection._read_packet()
  File "/home/ming/.env/blog/lib/python3.5/site-packages/pymysql/connections.py", line 1014, in _read_packet
    packet.check_error()
  File "/home/ming/.env/blog/lib/python3.5/site-packages/pymysql/connections.py", line 393, in check_error
    err.raise_mysql_exception(self._data)
  File "/home/ming/.env/blog/lib/python3.5/site-packages/pymysql/err.py", line 107, in raise_mysql_exception
    raise errorclass(errno, errval)
pymysql.err.ProgrammingError: (1146, "Table 'blog.app_article' doesn't exist")

The above exception was the direct cause of the following exception:

Traceback (most recent call last):
  File "/home/ming/.env/blog/lib/python3.5/site-packages/django/core/handlers/exception.py", line 39, in inner
    response = get_response(request)
  File "/home/ming/.env/blog/lib/python3.5/site-packages/django/core/handlers/base.py", line 187, in _get_response
    response = self.process_exception_by_middleware(e, request)
  File "/home/ming/.env/blog/lib/python3.5/site-packages/django/core/handlers/base.py", line 185, in _get_response
    response = wrapped_callback(request, *callback_args, **callback_kwargs)
  File "/home/ming/.env/blog/lib/python3.5/site-packages/django/views/generic/base.py", line 68, in view
    return self.dispatch(request, *args, **kwargs)
  File "/home/ming/.env/blog/lib/python3.5/site-packages/django/views/generic/base.py", line 88, in dispatch
    return handler(request, *args, **kwargs)
  File "/home/ming/.env/blog/lib/python3.5/site-packages/django/views/generic/list.py", line 159, in get
    self.object_list = self.get_queryset()
  File "/home/ming/projects/blog/app/views.py", line 29, in get_queryset
    for article in article_list:
  File "/home/ming/.env/blog/lib/python3.5/site-packages/django/db/models/query.py", line 256, in __iter__
    self._fetch_all()
  File "/home/ming/.env/blog/lib/python3.5/site-packages/django/db/models/query.py", line 1087, in _fetch_all
    self._result_cache = list(self.iterator())
  File "/home/ming/.env/blog/lib/python3.5/site-packages/django/db/models/query.py", line 54, in __iter__
    results = compiler.execute_sql()
  File "/home/ming/.env/blog/lib/python3.5/site-packages/django/db/models/sql/compiler.py", line 835, in execute_sql
    cursor.execute(sql, params)
  File "/home/ming/.env/blog/lib/python3.5/site-packages/django/db/backends/utils.py", line 79, in execute
    return super(CursorDebugWrapper, self).execute(sql, params)
  File "/home/ming/.env/blog/lib/python3.5/site-packages/django/db/backends/utils.py", line 64, in execute
    return self.cursor.execute(sql, params)
  File "/home/ming/.env/blog/lib/python3.5/site-packages/django/db/utils.py", line 94, in __exit__
    six.reraise(dj_exc_type, dj_exc_value, traceback)
  File "/home/ming/.env/blog/lib/python3.5/site-packages/django/utils/six.py", line 685, in reraise
    raise value.with_traceback(tb)
  File "/home/ming/.env/blog/lib/python3.5/site-packages/django/db/backends/utils.py", line 64, in execute
    return self.cursor.execute(sql, params)
  File "/home/ming/.env/blog/lib/python3.5/site-packages/django/db/backends/mysql/base.py", line 112, in execute
    return self.cursor.execute(query, args)
  File "/home/ming/.env/blog/lib/python3.5/site-packages/pymysql/cursors.py", line 166, in execute
    result = self._query(query)
  File "/home/ming/.env/blog/lib/python3.5/site-packages/pymysql/cursors.py", line 322, in _query
    conn.query(q)
  File "/home/ming/.env/blog/lib/python3.5/site-packages/pymysql/connections.py", line 856, in query
    self._affected_rows = self._read_query_result(unbuffered=unbuffered)
  File "/home/ming/.env/blog/lib/python3.5/site-packages/pymysql/connections.py", line 1057, in _read_query_result
    result.read()
  File "/home/ming/.env/blog/lib/python3.5/site-packages/pymysql/connections.py", line 1340, in read
    first_packet = self.connection._read_packet()
  File "/home/ming/.env/blog/lib/python3.5/site-packages/pymysql/connections.py", line 1014, in _read_packet
    packet.check_error()
  File "/home/ming/.env/blog/lib/python3.5/site-packages/pymysql/connections.py", line 393, in check_error
    err.raise_mysql_exception(self._data)
  File "/home/ming/.env/blog/lib/python3.5/site-packages/pymysql/err.py", line 107, in raise_mysql_exception
    raise errorclass(errno, errval)
django.db.utils.ProgrammingError: (1146, "Table 'blog.app_article' doesn't exist")
ERROR 2017-10-07 10:24:31,582 views 13373 140030823622400 邮件发送失败: Error 111 connecting to localhost:6379. Connection refused.
ERROR 2017-10-07 11:02:40,385 views 26434 139984518506240 邮件发送失败: (535, b'5.7.8 authentication failed')
ERROR 2017-10-07 11:03:13,011 views 26595 140543109977856 邮件发送失败: (535, b'5.7.12 SMTP access disabled')
ERROR 2017-12-13 18:39:39,191 exception 11240 6528 Internal Server Error: /
Traceback (most recent call last):
  File "E:\pywork\blog\blog\lib\site-packages\django\core\handlers\exception.py", line 39, in inner
    response = get_response(request)
  File "E:\pywork\blog\blog\lib\site-packages\django\core\handlers\base.py", line 217, in _get_response
    response = self.process_exception_by_middleware(e, request)
  File "E:\pywork\blog\blog\lib\site-packages\django\core\handlers\base.py", line 215, in _get_response
    response = response.render()
  File "E:\pywork\blog\blog\lib\site-packages\django\template\response.py", line 109, in render
    self.content = self.rendered_content
  File "E:\pywork\blog\blog\lib\site-packages\django\template\response.py", line 84, in rendered_content
    template = self.resolve_template(self.template_name)
  File "E:\pywork\blog\blog\lib\site-packages\django\template\response.py", line 66, in resolve_template
    return select_template(template, using=self.using)
  File "E:\pywork\blog\blog\lib\site-packages\django\template\loader.py", line 44, in select_template
    engines = _engine_list(using)
  File "E:\pywork\blog\blog\lib\site-packages\django\template\loader.py", line 72, in _engine_list
    return engines.all() if using is None else [engines[using]]
  File "E:\pywork\blog\blog\lib\site-packages\django\template\utils.py", line 89, in all
    return [self[alias] for alias in self]
  File "E:\pywork\blog\blog\lib\site-packages\django\template\utils.py", line 80, in __getitem__
    engine = engine_cls(params)
  File "E:\pywork\blog\blog\lib\site-packages\django\template\backends\django.py", line 30, in __init__
    options['libraries'] = self.get_templatetag_libraries(libraries)
  File "E:\pywork\blog\blog\lib\site-packages\django\template\backends\django.py", line 48, in get_templatetag_libraries
    libraries = get_installed_libraries()
  File "E:\pywork\blog\blog\lib\site-packages\django\template\backends\django.py", line 113, in get_installed_libraries
    for name in get_package_libraries(pkg):
  File "E:\pywork\blog\blog\lib\site-packages\django\template\backends\django.py", line 126, in get_package_libraries
    module = import_module(entry[1])
  File "c:\python27\Lib\importlib\__init__.py", line 37, in import_module
    __import__(name)
  File "E:\pywork\blog\app\templatetags\paginate_tags.py", line 5
SyntaxError: Non-ASCII character '\xe8' in file E:\pywork\blog\app\templatetags\paginate_tags.py on line 5, but no encoding declared; see http://python.org/dev/peps/pep-0263/ for details
ERROR 2017-12-13 18:41:44,229 exception 11240 10700 Internal Server Error: /
Traceback (most recent call last):
  File "E:\pywork\blog\blog\lib\site-packages\django\core\handlers\exception.py", line 39, in inner
    response = get_response(request)
  File "E:\pywork\blog\blog\lib\site-packages\django\core\handlers\base.py", line 217, in _get_response
    response = self.process_exception_by_middleware(e, request)
  File "E:\pywork\blog\blog\lib\site-packages\django\core\handlers\base.py", line 215, in _get_response
    response = response.render()
  File "E:\pywork\blog\blog\lib\site-packages\django\template\response.py", line 109, in render
    self.content = self.rendered_content
  File "E:\pywork\blog\blog\lib\site-packages\django\template\response.py", line 84, in rendered_content
    template = self.resolve_template(self.template_name)
  File "E:\pywork\blog\blog\lib\site-packages\django\template\response.py", line 66, in resolve_template
    return select_template(template, using=self.using)
  File "E:\pywork\blog\blog\lib\site-packages\django\template\loader.py", line 44, in select_template
    engines = _engine_list(using)
  File "E:\pywork\blog\blog\lib\site-packages\django\template\loader.py", line 72, in _engine_list
    return engines.all() if using is None else [engines[using]]
  File "E:\pywork\blog\blog\lib\site-packages\django\template\utils.py", line 89, in all
    return [self[alias] for alias in self]
  File "E:\pywork\blog\blog\lib\site-packages\django\template\utils.py", line 80, in __getitem__
    engine = engine_cls(params)
  File "E:\pywork\blog\blog\lib\site-packages\django\template\backends\django.py", line 30, in __init__
    options['libraries'] = self.get_templatetag_libraries(libraries)
  File "E:\pywork\blog\blog\lib\site-packages\django\template\backends\django.py", line 48, in get_templatetag_libraries
    libraries = get_installed_libraries()
  File "E:\pywork\blog\blog\lib\site-packages\django\template\backends\django.py", line 113, in get_installed_libraries
    for name in get_package_libraries(pkg):
  File "E:\pywork\blog\blog\lib\site-packages\django\template\backends\django.py", line 126, in get_package_libraries
    module = import_module(entry[1])
  File "c:\python27\Lib\importlib\__init__.py", line 37, in import_module
    __import__(name)
  File "E:\pywork\blog\app\templatetags\paginate_tags.py", line 5
SyntaxError: Non-ASCII character '\xe8' in file E:\pywork\blog\app\templatetags\paginate_tags.py on line 5, but no encoding declared; see http://python.org/dev/peps/pep-0263/ for details
ERROR 2017-12-13 18:41:55,109 exception 8516 10756 Internal Server Error: /
Traceback (most recent call last):
  File "E:\pywork\blog\blog\lib\site-packages\django\core\handlers\exception.py", line 39, in inner
    response = get_response(request)
  File "E:\pywork\blog\blog\lib\site-packages\django\core\handlers\base.py", line 217, in _get_response
    response = self.process_exception_by_middleware(e, request)
  File "E:\pywork\blog\blog\lib\site-packages\django\core\handlers\base.py", line 215, in _get_response
    response = response.render()
  File "E:\pywork\blog\blog\lib\site-packages\django\template\response.py", line 109, in render
    self.content = self.rendered_content
  File "E:\pywork\blog\blog\lib\site-packages\django\template\response.py", line 84, in rendered_content
    template = self.resolve_template(self.template_name)
  File "E:\pywork\blog\blog\lib\site-packages\django\template\response.py", line 66, in resolve_template
    return select_template(template, using=self.using)
  File "E:\pywork\blog\blog\lib\site-packages\django\template\loader.py", line 44, in select_template
    engines = _engine_list(using)
  File "E:\pywork\blog\blog\lib\site-packages\django\template\loader.py", line 72, in _engine_list
    return engines.all() if using is None else [engines[using]]
  File "E:\pywork\blog\blog\lib\site-packages\django\template\utils.py", line 89, in all
    return [self[alias] for alias in self]
  File "E:\pywork\blog\blog\lib\site-packages\django\template\utils.py", line 80, in __getitem__
    engine = engine_cls(params)
  File "E:\pywork\blog\blog\lib\site-packages\django\template\backends\django.py", line 30, in __init__
    options['libraries'] = self.get_templatetag_libraries(libraries)
  File "E:\pywork\blog\blog\lib\site-packages\django\template\backends\django.py", line 48, in get_templatetag_libraries
    libraries = get_installed_libraries()
  File "E:\pywork\blog\blog\lib\site-packages\django\template\backends\django.py", line 113, in get_installed_libraries
    for name in get_package_libraries(pkg):
  File "E:\pywork\blog\blog\lib\site-packages\django\template\backends\django.py", line 126, in get_package_libraries
    module = import_module(entry[1])
  File "c:\python27\Lib\importlib\__init__.py", line 37, in import_module
    __import__(name)
  File "E:\pywork\blog\app\templatetags\paginate_tags.py", line 5
SyntaxError: Non-ASCII character '\xe8' in file E:\pywork\blog\app\templatetags\paginate_tags.py on line 5, but no encoding declared; see http://python.org/dev/peps/pep-0263/ for details
ERROR 2017-12-13 18:43:19,665 exception 7208 10892 Internal Server Error: /
Traceback (most recent call last):
  File "E:\pywork\blog\blog\lib\site-packages\django\core\handlers\exception.py", line 39, in inner
    response = get_response(request)
  File "E:\pywork\blog\blog\lib\site-packages\django\core\handlers\base.py", line 217, in _get_response
    response = self.process_exception_by_middleware(e, request)
  File "E:\pywork\blog\blog\lib\site-packages\django\core\handlers\base.py", line 215, in _get_response
    response = response.render()
  File "E:\pywork\blog\blog\lib\site-packages\django\template\response.py", line 109, in render
    self.content = self.rendered_content
  File "E:\pywork\blog\blog\lib\site-packages\django\template\response.py", line 84, in rendered_content
    template = self.resolve_template(self.template_name)
  File "E:\pywork\blog\blog\lib\site-packages\django\template\response.py", line 66, in resolve_template
    return select_template(template, using=self.using)
  File "E:\pywork\blog\blog\lib\site-packages\django\template\loader.py", line 44, in select_template
    engines = _engine_list(using)
  File "E:\pywork\blog\blog\lib\site-packages\django\template\loader.py", line 72, in _engine_list
    return engines.all() if using is None else [engines[using]]
  File "E:\pywork\blog\blog\lib\site-packages\django\template\utils.py", line 89, in all
    return [self[alias] for alias in self]
  File "E:\pywork\blog\blog\lib\site-packages\django\template\utils.py", line 80, in __getitem__
    engine = engine_cls(params)
  File "E:\pywork\blog\blog\lib\site-packages\django\template\backends\django.py", line 30, in __init__
    options['libraries'] = self.get_templatetag_libraries(libraries)
  File "E:\pywork\blog\blog\lib\site-packages\django\template\backends\django.py", line 48, in get_templatetag_libraries
    libraries = get_installed_libraries()
  File "E:\pywork\blog\blog\lib\site-packages\django\template\backends\django.py", line 113, in get_installed_libraries
    for name in get_package_libraries(pkg):
  File "E:\pywork\blog\blog\lib\site-packages\django\template\backends\django.py", line 126, in get_package_libraries
    module = import_module(entry[1])
  File "c:\python27\Lib\importlib\__init__.py", line 37, in import_module
    __import__(name)
  File "E:\pywork\blog\app\templatetags\paginate_tags.py", line 5
SyntaxError: Non-ASCII character '\xe8' in file E:\pywork\blog\app\templatetags\paginate_tags.py on line 5, but no encoding declared; see http://python.org/dev/peps/pep-0263/ for details
ERROR 2017-12-13 18:44:11,198 exception 7412 10484 Internal Server Error: /
Traceback (most recent call last):
  File "E:\pywork\blog\blog\lib\site-packages\django\core\handlers\exception.py", line 39, in inner
    response = get_response(request)
  File "E:\pywork\blog\blog\lib\site-packages\django\core\handlers\base.py", line 217, in _get_response
    response = self.process_exception_by_middleware(e, request)
  File "E:\pywork\blog\blog\lib\site-packages\django\core\handlers\base.py", line 215, in _get_response
    response = response.render()
  File "E:\pywork\blog\blog\lib\site-packages\django\template\response.py", line 109, in render
    self.content = self.rendered_content
  File "E:\pywork\blog\blog\lib\site-packages\django\template\response.py", line 84, in rendered_content
    template = self.resolve_template(self.template_name)
  File "E:\pywork\blog\blog\lib\site-packages\django\template\response.py", line 66, in resolve_template
    return select_template(template, using=self.using)
  File "E:\pywork\blog\blog\lib\site-packages\django\template\loader.py", line 44, in select_template
    engines = _engine_list(using)
  File "E:\pywork\blog\blog\lib\site-packages\django\template\loader.py", line 72, in _engine_list
    return engines.all() if using is None else [engines[using]]
  File "E:\pywork\blog\blog\lib\site-packages\django\template\utils.py", line 89, in all
    return [self[alias] for alias in self]
  File "E:\pywork\blog\blog\lib\site-packages\django\template\utils.py", line 80, in __getitem__
    engine = engine_cls(params)
  File "E:\pywork\blog\blog\lib\site-packages\django\template\backends\django.py", line 30, in __init__
    options['libraries'] = self.get_templatetag_libraries(libraries)
  File "E:\pywork\blog\blog\lib\site-packages\django\template\backends\django.py", line 48, in get_templatetag_libraries
    libraries = get_installed_libraries()
  File "E:\pywork\blog\blog\lib\site-packages\django\template\backends\django.py", line 113, in get_installed_libraries
    for name in get_package_libraries(pkg):
  File "E:\pywork\blog\blog\lib\site-packages\django\template\backends\django.py", line 126, in get_package_libraries
    module = import_module(entry[1])
  File "c:\python27\Lib\importlib\__init__.py", line 37, in import_module
    __import__(name)
  File "E:\pywork\blog\app\templatetags\paginate_tags.py", line 5
SyntaxError: Non-ASCII character '\xe8' in file E:\pywork\blog\app\templatetags\paginate_tags.py on line 5, but no encoding declared; see http://python.org/dev/peps/pep-0263/ for details
ERROR 2017-12-13 18:45:36,464 exception 11208 10324 Internal Server Error: /
Traceback (most recent call last):
  File "E:\pywork\blog\blog\lib\site-packages\django\core\handlers\exception.py", line 39, in inner
    response = get_response(request)
  File "E:\pywork\blog\blog\lib\site-packages\django\core\handlers\base.py", line 217, in _get_response
    response = self.process_exception_by_middleware(e, request)
  File "E:\pywork\blog\blog\lib\site-packages\django\core\handlers\base.py", line 215, in _get_response
    response = response.render()
  File "E:\pywork\blog\blog\lib\site-packages\django\template\response.py", line 109, in render
    self.content = self.rendered_content
  File "E:\pywork\blog\blog\lib\site-packages\django\template\response.py", line 84, in rendered_content
    template = self.resolve_template(self.template_name)
  File "E:\pywork\blog\blog\lib\site-packages\django\template\response.py", line 66, in resolve_template
    return select_template(template, using=self.using)
  File "E:\pywork\blog\blog\lib\site-packages\django\template\loader.py", line 44, in select_template
    engines = _engine_list(using)
  File "E:\pywork\blog\blog\lib\site-packages\django\template\loader.py", line 72, in _engine_list
    return engines.all() if using is None else [engines[using]]
  File "E:\pywork\blog\blog\lib\site-packages\django\template\utils.py", line 89, in all
    return [self[alias] for alias in self]
  File "E:\pywork\blog\blog\lib\site-packages\django\template\utils.py", line 80, in __getitem__
    engine = engine_cls(params)
  File "E:\pywork\blog\blog\lib\site-packages\django\template\backends\django.py", line 30, in __init__
    options['libraries'] = self.get_templatetag_libraries(libraries)
  File "E:\pywork\blog\blog\lib\site-packages\django\template\backends\django.py", line 48, in get_templatetag_libraries
    libraries = get_installed_libraries()
  File "E:\pywork\blog\blog\lib\site-packages\django\template\backends\django.py", line 113, in get_installed_libraries
    for name in get_package_libraries(pkg):
  File "E:\pywork\blog\blog\lib\site-packages\django\template\backends\django.py", line 126, in get_package_libraries
    module = import_module(entry[1])
  File "c:\python27\Lib\importlib\__init__.py", line 37, in import_module
    __import__(name)
  File "E:\pywork\blog\app\templatetags\paginate_tags.py", line 5
SyntaxError: Non-ASCII character '\xe8' in file E:\pywork\blog\app\templatetags\paginate_tags.py on line 5, but no encoding declared; see http://python.org/dev/peps/pep-0263/ for details
